<?xml version="1.0"?>
<robot xmlns:xacro="http://www.ros.org/wiki/xacro">
  <!-- Properties for the model -->
  <xacro:property name="box_size" value="0.102"/>
  <xacro:property name="cylinder_length" value="0.01"/>
  <xacro:property name="cylinder_radius" value="0.025"/>
  
  <!-- Properties for dynamic angle link -->
  <xacro:property name="pointer_length" value="${cylinder_radius}"/>
  <xacro:property name="pointer_width" value="0.002"/>
  <xacro:property name="pointer_height" value="0.002"/> <!-- Height of the angle link -->
  <xacro:property name="small_box_size" value="${pointer_length} ${pointer_width} ${pointer_height}"/>

  <!-- Macro definition with prefix parameter -->
  <xacro:macro name="joint_model" params="prefix">
    <!-- Base link -->
    <link name="${prefix}base_link"/>

    <!-- Stator link -->
    <link name="${prefix}stator_link">
      <visual>
        <geometry>
          <box size="${box_size} ${box_size} ${box_size}"/>
        </geometry>
        <material name="black">
          <color rgba="0 0 0 1"/>
        </material>
      </visual>
    </link>

    <!-- Rotor link -->
    <link name="${prefix}rotor_link">
      <visual>
        <geometry>
          <cylinder length="${cylinder_length}" radius="${cylinder_radius}"/>
        </geometry>
        <material name="red">
          <color rgba="1 0 0 1"/>
        </material>
      </visual>
    </link>

    <!-- Angle link positioned on top of the rotor -->
    <link name="${prefix}angle_link">
      <visual>
        <!-- Offset to extend from center to radius and place on top -->
        <origin xyz="${pointer_length / 2} 0 ${pointer_height / 2}" rpy="0 0 0"/>
        <geometry>
          <box size="${small_box_size}"/>
        </geometry>
        <material name="white">
          <color rgba="1 1 1 1"/>
        </material>
      </visual>
    </link>

    <!-- Stator joint -->
    <joint name="${prefix}stator_joint" type="fixed">
      <parent link="${prefix}base_link"/>
      <child link="${prefix}stator_link"/>
      <origin xyz="0 0 ${box_size/2}"/>
    </joint>

    <!-- Angle joint -->
    <joint name="${prefix}angle" type="revolute">
      <parent link="${prefix}stator_link"/>
      <child link="${prefix}rotor_link"/>
      <origin xyz="0 0 ${box_size/2}"/>
      <axis xyz="0 0 1"/>
      <limit lower="-3.14159" upper="3.14159" effort="1.0" velocity="1.0"/>
    </joint>

    <!-- Indicator joint adjusted to place angle link on top of the rotor -->
    <joint name="${prefix}indicator" type="fixed">
      <parent link="${prefix}rotor_link"/>
      <child link="${prefix}angle_link"/>
      <origin xyz="0 0 ${cylinder_length / 2}" rpy="0 0 0"/>
    </joint>
  </xacro:macro>
</robot>